Workbook

Sheet MoM Brand Wise
A1: Brand ID | B1: Brand Name | C1: Manager | D1: Jan'25 | I1: Feb'25 | N1: Mar'25 | S1: Apr'25 | X1: May'25 | AC1: Jun'25 | AH1: Jul'25 | AM1: Aug'25 | AR1: Sept'25 | AW1: Oct'25 | BB1: Overall'25
D2: ISW +WTS + Influencer+LLM Audit Counts | E2: Makers TP Counts | F2: Suppression Count | G2: Precision % | H2: Variance | I2: ISW +WTS + Influencer+LLM Audit Counts | J2: Makers TP Counts | K2: Suppression Count | L2: Precision % | M2: Variance | N2: ISW +WTS + Influencer+LLM Audit Counts | O2: Makers TP Counts | P2: Suppression Count | Q2: Precision % | R2: Variance | S2: ISW +WTS + Influencer+LLM Audit Counts | T2: Makers TP Counts | U2: Suppression Count | V2: Precision % | W2: Variance | X2: ISW +WTS + Influencer+LLM Audit Counts | Y2: Makers TP Counts | Z2: Suppression Count | AA2: Precision % | AB2: Variance | AC2: ISW +WTS + Influencer+LLM Audit Counts | AD2: Makers TP Counts | AE2: Suppression Count | AF2: Precision % | AG2: Variance | AH2: ISW +WTS + Influencer+LLM Audit Counts | AI2: Makers TP Counts | AJ2: Suppression Count | AK2: Precision % | AL2: Variance | AM2: ISW +WTS + Influencer+LLM Audit Counts | AN2: Makers TP Counts | AO2: Suppression Count | AP2: Precision % | AQ2: Variance | AR2: ISW +WTS + Influencer+LLM Audit Counts | AS2: Makers TP Counts | AT2: Suppression Count | AU2: Precision % | AV2: Variance | AW2: ISW +WTS + Influencer+LLM Audit Counts | AX2: Makers TP Counts | AY2: Suppression Count | AZ2: Precision % | BA2: Variance | BB2: ISW +WTS + Influencer+LLM Audit Counts | BC2: Makers TP Counts | BD2: Suppression Count | BE2: Precision % | BF2: Variance
A3: 326424 | B3: MagSafe | C3: Siddharth | D3: 76067 | E3: 73085 | F3: 73005 | G3: =F3/D3 -> 0.95974601 | H3: =F3-E3 -> -80 | I3: 18959 | J3: 6323 | K3: 6341 | L3: =K3/I3 -> 0.33445857 | M3: =K3-J3 -> 18 | N3: 10581 | O3: 3404 | P3: 3404 | Q3: =P3/N3 -> 0.32170872 | R3: =P3-O3 -> 0 | S3: 30167 | T3: 8960 | U3: 8937 | V3: =U3/S3 -> 0.29625087 | W3: =U3-T3 -> -23 | X3: 28799 | Y3: 15069 | Z3: 15059 | AA3: =Z3/X3 -> 0.5229001 | AB3: =Z3-Y3 -> -10 | AC3: 24848 | AD3: 6980 | AE3: 6565 | AF3: =AE3/AC3 -> 0.26420637 | AG3: =AE3-AD3 -> -415 | AH3: 17268 | AI3: 3909 | AJ3: 3807 | AK3: =AJ3/AH3 -> 0.2204656 | AM3: 19435 | AN3: 4961 | AO3: 2564 | AP3: =AO3/AM3 -> 0.13192694 | AR3: 41489 | AS3: 1255 | AT3: 1072 | AU3: =AT3/AR3 -> 0.025838174 | AV3: =AT3-AS3 -> -183 | AW3: 26559 | AX3: 527 | AY3: 450 | AZ3: =AY3/AW3 -> 0.016943409 | BB3: =AR3+AC3+X3+S3+N3+I3+D3+AM3+AH3+AW3 -> 294172 | BC3: =AS3+AD3+Y3+T3+O3+J3+E3+AN3+AI3+AX3 -> 124473 | BD3: =AT3+AE3+Z3+U3+P3+K3+F3+AO3+AJ3+AY3 -> 121204 | BE3: =BD3/BB3 -> 0.41201746
A4: 326425 | B4: Lightning | C4: Siddharth | D4: 37562 | E4: 23588 | F4: 21178 | G4: =F4/D4 -> 0.56381449 | H4: =F4-E4 -> -2410 | I4: 52104 | J4: 17123 | K4: 16154 | L4: =K4/I4 -> 0.31003378 | M4: =K4-J4 -> -969 | N4: 27471 | O4: 7395 | P4: 7271 | Q4: =P4/N4 -> 0.26467912 | R4: =P4-O4 -> -124 | S4: 46847 | T4: 9335 | U4: 9293 | V4: =U4/S4 -> 0.19836916 | W4: =U4-T4 -> -42 | X4: 29621 | Y4: 14343 | Z4: 14317 | AA4: =Z4/X4 -> 0.48333952 | AB4: =Z4-Y4 -> -26 | AC4: 28639 | AD4: 9405 | AE4: 9397 | AF4: =AE4/AC4 -> 0.328119 | AG4: =AE4-AD4 -> -8 | AH4: 23060 | AI4: 8378 | AJ4: 7929 | AK4: =AJ4/AH4 -> 0.34384215 | AM4: 15458 | AN4: 2402 | AO4: 4384 | AP4: =AO4/AM4 -> 0.28360719 | AR4: 48447 | AS4: 7672 | AT4: 7236 | AU4: =AT4/AR4 -> 0.14935909 | AV4: =AT4-AS4 -> -436 | AW4: 54848 | AX4: 5776 | AY4: 4585 | AZ4: =AY4/AW4 -> 0.083594662 | BB4: =AR4+AC4+X4+S4+N4+I4+D4+AM4+AH4+AW4 -> 364057 | BC4: =AS4+AD4+Y4+T4+O4+J4+E4+AN4+AI4+AX4 -> 105417 | BD4: =AT4+AE4+Z4+U4+P4+K4+F4+AO4+AJ4+AY4 -> 101744 | BE4: =BD4/BB4 -> 0.27947272
A5: 242269 | B5: Porsche | C5: Siddharth | D5: 239 | E5: 122 | F5: 121 | G5: =F5/D5 -> 0.50627615 | H5: =F5-E5 -> -1 | I5: 16991 | J5: 1152 | K5: 962 | L5: =K5/I5 -> 0.05661821 | M5: =K5-J5 -> -190 | N5: 7723 | O5: 0 | P5: 0 | Q5: =P5/N5 -> 0 | R5: =P5-O5 -> 0 | S5: 854 | T5: 21 | U5: 24 | V5: =U5/S5 -> 0.028103044 | W5: =U5-T5 -> 3 | X5: 15155 | Y5: 1418 | Z5: 994 | AA5: =Z5/X5 -> 0.065588915 | AB5: =Z5-Y5 -> -424 | AC5: 12043 | AD5: 663 | AE5: 594 | AF5: =AE5/AC5 -> 0.049323258 | AG5: =AE5-AD5 -> -69 | AH5: 20350 | AI5: 749 | AJ5: 359 | AK5: =AJ5/AH5 -> 0.017641278 | AM5: 33218 | AN5: 1873 | AO5: 1531 | AP5: =AO5/AM5 -> 0.04608947 | AR5: 62026 | AS5: 1196 | AT5: 683 | AU5: =AT5/AR5 -> 0.011011511 | AV5: =AT5-AS5 -> -513 | AW5: 63047 | AX5: 1716 | AY5: 1246 | AZ5: =AY5/AW5 -> 0.019763034 | BB5: =AR5+AC5+X5+S5+N5+I5+D5+AM5+AH5+AW5 -> 231646 | BC5: =AS5+AD5+Y5+T5+O5+J5+E5+AN5+AI5+AX5 -> 8910 | BD5: =AT5+AE5+Z5+U5+P5+K5+F5+AO5+AJ5+AY5 -> 6514 | BE5: =BD5/BB5 -> 0.028120494
A6: 326696 | B6: MINI | C6: Siddharth | D6: 2442 | E6: 1471 | F6: 1048 | G6: =F6/D6 -> 0.42915643 | H6: =F6-E6 -> -423 | I6: 1400 | J6: 888 | K6: 738 | L6: =K6/I6 -> 0.52714286 | M6: =K6-J6 -> -150 | N6: 1767 | O6: 615 | P6: 501 | Q6: =P6/N6 -> 0.28353141 | R6: =P6-O6 -> -114 | S6: 1681 | T6: 400 | U6: 234 | V6: =U6/S6 -> 0.13920286 | W6: =U6-T6 -> -166 | X6: 3877 | Y6: 128 | Z6: 29 | AA6: =Z6/X6 -> 0.0074800103 | AB6: =Z6-Y6 -> -99 | AC6: 6490 | AD6: 284 | AE6: 273 | AF6: =AE6/AC6 -> 0.042064715 | AG6: =AE6-AD6 -> -11 | AH6: 1240 | AI6: 476 | AJ6: 453 | AK6: =AJ6/AH6 -> 0.36532258 | AM6: 11110 | AN6: 276 | AO6: 165 | AP6: =AO6/AM6 -> 0.014851485 | AR6: 8996 | AS6: 419 | AT6: 152 | AU6: =AT6/AR6 -> 0.016896398 | AV6: =AT6-AS6 -> -267 | AW6: 328 | AX6: 272 | AY6: 193 | AZ6: =AY6/AW6 -> 0.58841463 | BB6: =AR6+AC6+X6+S6+N6+I6+D6+AM6+AH6+AW6 -> 39331 | BC6: =AS6+AD6+Y6+T6+O6+J6+E6+AN6+AI6+AX6 -> 5229 | BD6: =AT6+AE6+Z6+U6+P6+K6+F6+AO6+AJ6+AY6 -> 3786 | BE6: =BD6/BB6 -> 0.096259948
A7: 110955 | B7: Apple | C7: Siddharth | D7: 68112 | E7: 15950 | F7: 20293 | G7: =F7/D7 -> 0.29793575 | H7: =F7-E7 -> 4343 | I7: 81796 | J7: 14546 | K7: 13790 | L7: =K7/I7 -> 0.16859015 | M7: =K7-J7 -> -756 | N7: 63600 | O7: 18118 | P7: 16798 | Q7: =P7/N7 -> 0.2641195 | R7: =P7-O7 -> -1320 | S7: 75102 | T7: 16663 | U7: 15360 | V7: =U7/S7 -> 0.20452185 | W7: =U7-T7 -> -1303 | X7: 64719 | Y7: 27953 | Z7: 26096 | AA7: =Z7/X7 -> 0.40322007 | AB7: =Z7-Y7 -> -1857 | AC7: 40450 | AD7: 7339 | AE7: 8355 | AF7: =AE7/AC7 -> 0.2065513 | AG7: =AE7-AD7 -> 1016 | AH7: 55291 | AI7: 7397 | AJ7: 6665 | AK7: =AJ7/AH7 -> 0.12054403 | AM7: 74583 | AN7: 8572 | AO7: 7709 | AP7: =AO7/AM7 -> 0.10336136 | AR7: 170623 | AS7: 27355 | AT7: 24062 | AU7: =AT7/AR7 -> 0.14102436 | AV7: =AT7-AS7 -> -3293 | AW7: 145996 | AX7: 24004 | AY7: 27042 | AZ7: =AY7/AW7 -> 0.18522425 | BB7: =AR7+AC7+X7+S7+N7+I7+D7+AM7+AH7+AW7 -> 840272 | BC7: =AS7+AD7+Y7+T7+O7+J7+E7+AN7+AI7+AX7 -> 167897 | BD7: =AT7+AE7+Z7+U7+P7+K7+F7+AO7+AJ7+AY7 -> 166170 | BE7: =BD7/BB7 -> 0.19775739
A8: 213407 | B8: Chevrolet | C8: Siddharth | D8: 58235 | E8: 19937 | F8: 15775 | G8: =F8/D8 -> 0.27088521 | H8: =F8-E8 -> -4162 | I8: 65023 | J8: 11347 | K8: 9146 | L8: =K8/I8 -> 0.14065792 | M8: =K8-J8 -> -2201 | N8: 48775 | O8: 9158 | P8: 6962 | Q8: =P8/N8 -> 0.14273706 | R8: =P8-O8 -> -2196 | S8: 59668 | T8: 16736 | U8: 14485 | V8: =U8/S8 -> 0.24275994 | W8: =U8-T8 -> -2251 | X8: 37225 | Y8: 7185 | Z8: 5783 | AA8: =Z8/X8 -> 0.15535259 | AB8: =Z8-Y8 -> -1402 | AC8: 16071 | AD8: 3047 | AE8: 2435 | AF8: =AE8/AC8 -> 0.15151515 | AG8: =AE8-AD8 -> -612 | AH8: 14616 | AI8: 1534 | AJ8: 1450 | AK8: =AJ8/AH8 -> 0.099206349 | AM8: 48512 | AN8: 4102 | AO8: 3208 | AP8: =AO8/AM8 -> 0.066127968 | AR8: 21785 | AS8: 372 | AT8: 179 | AU8: =AT8/AR8 -> 0.0082166628 | AV8: =AT8-AS8 -> -193 | AW8: 18179 | AX8: 218 | AY8: 57 | AZ8: =AY8/AW8 -> 0.003135486 | BB8: =AR8+AC8+X8+S8+N8+I8+D8+AM8+AH8+AW8 -> 388089 | BC8: =AS8+AD8+Y8+T8+O8+J8+E8+AN8+AI8+AX8 -> 73636 | BD8: =AT8+AE8+Z8+U8+P8+K8+F8+AO8+AJ8+AY8 -> 59480 | BE8: =BD8/BB8 -> 0.15326381
A9: 553871 | B9: SWOOSH | C9: Siddharth | D9: 50632 | E9: 16520 | F9: 13063 | G9: =F9/D9 -> 0.25799889 | H9: =F9-E9 -> -3457 | I9: 33130 | J9: 9991 | K9: 8440 | L9: =K9/I9 -> 0.254754 | M9: =K9-J9 -> -1551 | N9: 19990 | O9: 4997 | P9: 5695 | Q9: =P9/N9 -> 0.28489245 | R9: =P9-O9 -> 698 | S9: 37861 | T9: 7987 | U9: 6972 | V9: =U9/S9 -> 0.18414728 | W9: =U9-T9 -> -1015 | X9: 49660 | Y9: 6743 | Z9: 6903 | AA9: =Z9/X9 -> 0.13900524 | AB9: =Z9-Y9 -> 160 | AC9: 32179 | AD9: 4346 | AE9: 3553 | AF9: =AE9/AC9 -> 0.11041362 | AG9: =AE9-AD9 -> -793 | AH9: 169981 | AI9: 56033 | AJ9: 68758 | AK9: =AJ9/AH9 -> 0.40450403 | AM9: 430286 | AN9: 294156 | AO9: 248225 | AP9: =AO9/AM9 -> 0.57688375 | AR9: 157767 | AS9: 138538 | AT9: 122335 | AU9: =AT9/AR9 -> 0.77541564 | AV9: =AT9-AS9 -> -16203 | AW9: 102214 | AX9: 87553 | AY9: 105479 | AZ9: =AY9/AW9 -> 1.0319428 | BB9: =AR9+AC9+X9+S9+N9+I9+D9+AM9+AH9+AW9 -> 1083700 | BC9: =AS9+AD9+Y9+T9+O9+J9+E9+AN9+AI9+AX9 -> 626864 | BD9: =AT9+AE9+Z9+U9+P9+K9+F9+AO9+AJ9+AY9 -> 589423 | BE9: =BD9/BB9 -> 0.54389868
A10: 338695 | B10: BULLI | C10: Siddharth | D10: 60569 | E10: 15337 | F10: 15369 | G10: =F10/D10 -> 0.25374366 | H10: =F10-E10 -> 32 | I10: 50402 | J10: 14080 | K10: 10445 | L10: =K10/I10 -> 0.20723384 | M10: =K10-J10 -> -3635 | N10: 28019 | O10: 9573 | P10: 11952 | Q10: =P10/N10 -> 0.42656769 | R10: =P10-O10 -> 2379 | S10: 38862 | T10: 13893 | U10: 12554 | V10: =U10/S10 -> 0.3230405 | W10: =U10-T10 -> -1339 | X10: 38370 | Y10: 10700 | Z10: 8569 | AA10: =Z10/X10 -> 0.22332551 | AB10: =Z10-Y10 -> -2131 | AC10: 51762 | AD10: 15193 | AE10: 15506 | AF10: =AE10/AC10 -> 0.29956339 | AG10: =AE10-AD10 -> 313 | AH10: 24535 | AI10: 2988 | AJ10: 3158 | AK10: =AJ10/AH10 -> 0.12871408 | AM10: 11517 | AN10: 2549 | AO10: 1692 | AP10: =AO10/AM10 -> 0.14691326 | AR10: 36169 | AS10: 12512 | AT10: 10844 | AU10: =AT10/AR10 -> 0.29981476 | AV10: =AT10-AS10 -> -1668 | AW10: 39234 | AX10: 7085 | AY10: 4322 | AZ10: =AY10/AW10 -> 0.11015956 | BB10: =AR10+AC10+X10+S10+N10+I10+D10+AM10+AH10+AW10 -> 379439 | BC10: =AS10+AD10+Y10+T10+O10+J10+E10+AN10+AI10+AX10 -> 103910 | BD10: =AT10+AE10+Z10+U10+P10+K10+F10+AO10+AJ10+AY10 -> 94411 | BE10: =BD10/BB10 -> 0.24881733
A11: 326694 | B11: M | C11: Siddharth | D11: 50510 | E11: 13108 | F11: 12590 | G11: =F11/D11 -> 0.24925757 | H11: =F11-E11 -> -518 | I11: 40377 | J11: 16090 | K11: 12299 | L11: =K11/I11 -> 0.30460411 | M11: =K11-J11 -> -3791 | N11: 22132 | O11: 16650 | P11: 19518 | Q11: =P11/N11 -> 0.88189048 | R11: =P11-O11 -> 2868 | S11: 34508 | T11: 17931 | U11: 15937 | V11: =U11/S11 -> 0.46183494 | W11: =U11-T11 -> -1994 | X11: 43322 | Y11: 18600 | Z11: 14573 | AA11: =Z11/X11 -> 0.33638798 | AB11: =Z11-Y11 -> -4027 | AC11: 31047 | AD11: 22800 | AE11: 24118 | AF11: =AE11/AC11 -> 0.77682224 | AG11: =AE11-AD11 -> 1318 | AH11: 37170 | AI11: 26814 | AJ11: 24995 | AK11: =AJ11/AH11 -> 0.6724509 | AM11: 49173 | AN11: 16760 | AO11: 11967 | AP11: =AO11/AM11 -> 0.24336526 | AR11: 28814 | AS11: 23529 | AT11: 15689 | AU11: =AT11/AR11 -> 0.54449226 | AV11: =AT11-AS11 -> -7840 | AW11: 34820 | AX11: 21981 | AY11: 19323 | AZ11: =AY11/AW11 -> 0.55493969 | BB11: =AR11+AC11+X11+S11+N11+I11+D11+AM11+AH11+AW11 -> 371873 | BC11: =AS11+AD11+Y11+T11+O11+J11+E11+AN11+AI11+AX11 -> 194263 | BD11: =AT11+AE11+Z11+U11+P11+K11+F11+AO11+AJ11+AY11 -> 171009 | BE11: =BD11/BB11 -> 0.45985861
A12: 326429 | B12: Apple WATCH | C12: Siddharth | D12: 58999 | E12: 13746 | F12: 13646 | G12: =F12/D12 -> 0.23129206 | H12: =F12-E12 -> -100 | I12: 68790 | J12: 14875 | K12: 14354 | L12: =K12/I12 -> 0.20866405 | M12: =K12-J12 -> -521 | N12: 70241 | O12: 44126 | P12: 44075 | Q12: =P12/N12 -> 0.62748252 | R12: =P12-O12 -> -51 | S12: 40275 | T12: 8958 | U12: 8604 | V12: =U12/S12 -> 0.21363128 | W12: =U12-T12 -> -354 | X12: 35346 | Y12: 6875 | Z12: 6605 | AA12: =Z12/X12 -> 0.18686697 | AB12: =Z12-Y12 -> -270 | AC12: 37198 | AD12: 12538 | AE12: 9773 | AF12: =AE12/AC12 -> 0.26272918 | AG12: =AE12-AD12 -> -2765 | AH12: 49461 | AI12: 9607 | AJ12: 9212 | AK12: =AJ12/AH12 -> 0.18624775 | AM12: 103168 | AN12: 11661 | AO12: 12975 | AP12: =AO12/AM12 -> 0.12576574 | AR12: 144336 | AS12: 19073 | AT12: 17104 | AU12: =AT12/AR12 -> 0.11850127 | AV12: =AT12-AS12 -> -1969 | AW12: 126397 | AX12: 7824 | AY12: 10040 | AZ12: =AY12/AW12 -> 0.079432265 | BB12: =AR12+AC12+X12+S12+N12+I12+D12+AM12+AH12+AW12 -> 734211 | BC12: =AS12+AD12+Y12+T12+O12+J12+E12+AN12+AI12+AX12 -> 149283 | BD12: =AT12+AE12+Z12+U12+P12+K12+F12+AO12+AJ12+AY12 -> 146388 | BE12: =BD12/BB12 -> 0.19938138
A13: 338748 | B13: VOLKSWAGEN | C13: Siddharth | D13: 388 | E13: 114 | F13: 76 | G13: =F13/D13 -> 0.19587629 | H13: =F13-E13 -> -38 | I13: 622 | J13: 216 | K13: 70 | L13: =K13/I13 -> 0.11254019 | M13: =K13-J13 -> -146 | N13: 290 | O13: 47 | P13: 135 | Q13: =P13/N13 -> 0.46551724 | R13: =P13-O13 -> 88 | S13: 2850 | T13: 85 | U13: 64 | V13: =U13/S13 -> 0.02245614 | W13: =U13-T13 -> -21 | X13: 1161 | Y13: 18 | Z13: 42 | AA13: =Z13/X13 -> 0.036175711 | AB13: =Z13-Y13 -> 24 | AC13: 3584 | AD13: 76 | AE13: 8 | AF13: =AE13/AC13 -> 0.0022321429 | AG13: =AE13-AD13 -> -68 | AH13: 203 | AI13: 3 | AJ13: 4 | AK13: =AJ13/AH13 -> 0.019704433 | AM13: 4953 | AN13: 80 | AO13: 21 | AP13: =AO13/AM13 -> 0.0042398546 | AR13: 11218 | AS13: 360 | AT13: 172 | AU13: =AT13/AR13 -> 0.015332501 | AV13: =AT13-AS13 -> -188 | AW13: 3986 | AX13: 114 | AY13: 43 | AZ13: =AY13/AW13 -> 0.010787757 | BB13: =AR13+AC13+X13+S13+N13+I13+D13+AM13+AH13+AW13 -> 29255 | BC13: =AS13+AD13+Y13+T13+O13+J13+E13+AN13+AI13+AX13 -> 1113 | BD13: =AT13+AE13+Z13+U13+P13+K13+F13+AO13+AJ13+AY13 -> 635 | BE13: =BD13/BB13 -> 0.021705691
A14: 498419 | B14: JUMPMAN | C14: Siddharth | D14: 22808 | E14: 5069 | F14: 3781 | G14: =F14/D14 -> 0.16577517 | H14: =F14-E14 -> -1288 | I14: 15522 | J14: 6293 | K14: 5961 | L14: =K14/I14 -> 0.38403556 | M14: =K14-J14 -> -332 | N14: 19518 | O14: 4520 | P14: 3805 | Q14: =P14/N14 -> 0.19494825 | R14: =P14-O14 -> -715 | S14: 33704 | T14: 11601 | U14: 5088 | V14: =U14/S14 -> 0.15096131 | W14: =U14-T14 -> -6513 | X14: 51378 | Y14: 7960 | Z14: 3971 | AA14: =Z14/X14 -> 0.077289891 | AB14: =Z14-Y14 -> -3989 | AC14: 74140 | AD14: 10596 | AE14: 3624 | AF14: =AE14/AC14 -> 0.048880496 | AG14: =AE14-AD14 -> -6972 | AH14: 82416 | AI14: 7444 | AJ14: 2703 | AK14: =AJ14/AH14 -> 0.03279703 | AM14: 50566 | AN14: 2025 | AO14: 1154 | AP14: =AO14/AM14 -> 0.022821659 | AR14: 3892 | AS14: 2002 | AT14: 594 | AU14: =AT14/AR14 -> 0.15262076 | AV14: =AT14-AS14 -> -1408 | AW14: 8946 | AX14: 57 | AY14: 58 | AZ14: =AY14/AW14 -> 0.0064833445 | BB14: =AR14+AC14+X14+S14+N14+I14+D14+AM14+AH14+AW14 -> 362890 | BC14: =AS14+AD14+Y14+T14+O14+J14+E14+AN14+AI14+AX14 -> 57567 | BD14: =AT14+AE14+Z14+U14+P14+K14+F14+AO14+AJ14+AY14 -> 30739 | BE14: =BD14/BB14 -> 0.084706109
... A22: 422074 | B22: S LINE | C22: Siddharth | D22: 2420 | E22: 318 | F22: 247 | G22: =F22/D22 -> 0.10206612 | H22: =F22-E22 -> -71 | I22: 1163 | J22: 134 | K22: 104 | L22: =K22/I22 -> 0.089423904 | M22: =K22-J22 -> -30 | N22: 7973 | O22: 5839 | P22: 5562 | Q22: =P22/N22 -> 0.69760441 | R22: =P22-O22 -> -277 | S22: 3753 | T22: 710 | U22: 630 | V22: =U22/S22 -> 0.16786571 | W22: =U22-T22 -> -80 | X22: 4381 | Y22: 244 | Z22: 329 | AA22: =Z22/X22 -> 0.07509701 | AB22: =Z22-Y22 -> 85 | AC22: 9374 | AD22: 736 | AE22: 529 | AF22: =AE22/AC22 -> 0.056432686 | AG22: =AE22-AD22 -> -207 | AH22: 11364 | AI22: 934 | AJ22: 1371 | AK22: =AJ22/AH22 -> 0.12064414 | AM22: 87606 | AN22: 54494 | AO22: 67924 | AP22: =AO22/AM22 -> 0.77533502 | AR22: 3995 | AS22: 784 | AT22: 673 | AU22: =AT22/AR22 -> 0.16846058 | AV22: =AT22-AS22 -> -111 | AW22: 6783 | AX22: 381 | AY22: 279 | AZ22: =AY22/AW22 -> 0.041132242 | BB22: =AR22+AC22+X22+S22+N22+I22+D22+AM22+AH22+AW22 -> 138812 | BC22: =AS22+AD22+Y22+T22+O22+J22+E22+AN22+AI22+AX22 -> 64574 | BD22: =AT22+AE22+Z22+U22+P22+K22+F22+AO22+AJ22+AY22 -> 77648 | BE22: =BD22/BB22 -> 0.55937527
A23: 553982 | B23: K I | C23: Siddharth | D23: 2159 | E23: 259 | F23: 189 | G23: =F23/D23 -> 0.087540528 | H23: =F23-E23 -> -70 | I23: 647 | J23: 148 | K23: 108 | L23: =K23/I23 -> 0.16692427 | M23: =K23-J23 -> -40 | N23: 12 | O23: 12 | P23: 51 | Q23: =P23/N23 -> 4.25 | R23: =P23-O23 -> 39 | S23: 1136 | T23: 73 | U23: 64 | V23: =U23/S23 -> 0.056338028 | W23: =U23-T23 -> -9 | X23: 27 | Y23: 27 | Z23: 27 | AA23: =Z23/X23 -> 1 | AB23: =Z23-Y23 -> 0 | AC23: 24 | AD23: 24 | AE23: 24 | AF23: =AE23/AC23 -> 1 | AG23: =AE23-AD23 -> 0 | AH23: 4312 | AI23: 34 | AJ23: 33 | AK23: =AJ23/AH23 -> 0.0076530612 | AM23: 2676 | AN23: 0 | AP23: =AO23/AM23 -> 0 | AR23: 2684 | AS23: 0 | AU23: =AT23/AR23 -> 0 | AV23: =AT23-AS23 -> 0 | AW23: 513 | AX23: 0 | AZ23: =AY23/AW23 -> 0 | BB23: =AR23+AC23+X23+S23+N23+I23+D23+AM23+AH23+AW23 -> 14190 | BC23: =AS23+AD23+Y23+T23+O23+J23+E23+AN23+AI23+AX23 -> 577 | BD23: =AT23+AE23+Z23+U23+P23+K23+F23+AO23+AJ23+AY23 -> 496 | BE23: =BD23/BB23 -> 0.034954193
A24: 338933 | B24: Xiaomi | C24: Siddharth | D24: 2510 | E24: 215 | F24: 0 | G24: =F24/D24 -> 0 | H24: =F24-E24 -> -215 | I24: 7795 | J24: 0 | K24: 0 | L24: =K24/I24 -> 0 | M24: =K24-J24 -> 0 | N24: 0 | O24: 0 | P24: 0 | Q24: =P24/N24 -> #DIV/0! | R24: =P24-O24 -> 0 | S24: 982 | T24: 149 | U24: 46 | V24: =U24/S24 -> 0.046843177 | W24: =U24-T24 -> -103 | X24: 10122 | Y24: 1540 | Z24: 1535 | AA24: =Z24/X24 -> 0.15164987 | AB24: =Z24-Y24 -> -5 | AC24: 1000 | AD24: 1 | AE24: 1 | AF24: =AE24/AC24 -> 0.001 | AG24: =AE24-AD24 -> 0 | AH24: 8189 | AI24: 906 | AJ24: 1702 | AK24: =AJ24/AH24 -> 0.20783979 | AM24: 29080 | AN24: 2339 | AO24: 840 | AP24: =AO24/AM24 -> 0.028885832 | AR24: 13931 | AS24: 396 | AT24: 389 | AU24: =AT24/AR24 -> 0.027923336 | AV24: =AT24-AS24 -> -7 | AW24: 22035 | AX24: 723 | AY24: 625 | AZ24: =AY24/AW24 -> 0.028363966 | BB24: =AR24+AC24+X24+S24+N24+I24+D24+AM24+AH24+AW24 -> 95644 | BC24: =AS24+AD24+Y24+T24+O24+J24+E24+AN24+AI24+AX24 -> 6269 | BD24: =AT24+AE24+Z24+U24+P24+K24+F24+AO24+AJ24+AY24 -> 5138 | BE24: =BD24/BB24 -> 0.053720045
A25: 327281 | B25: AirPods | C25: Siddharth | D25: 28404 | E25: 2440 | F25: 2387 | G25: =F25/D25 -> 0.08403746 | H25: =F25-E25 -> -53 | I25: 28642 | J25: 2841 | K25: 2485 | L25: =K25/I25 -> 0.086760701 | M25: =K25-J25 -> -356 | N25: 38394 | O25: 3708 | P25: 3601 | Q25: =P25/N25 -> 0.093790696 | R25: =P25-O25 -> -107 | S25: 41270 | T25: 3511 | U25: 3378 | V25: =U25/S25 -> 0.081851224 | W25: =U25-T25 -> -133 | X25: 26248 | Y25: 1213 | Z25: 1186 | AA25: =Z25/X25 -> 0.045184395 | AB25: =Z25-Y25 -> -27 | AC25: 24993 | AD25: 1001 | AE25: 966 | AF25: =AE25/AC25 -> 0.038650822 | AG25: =AE25-AD25 -> -35 | AH25: 44284 | AI25: 3644 | AJ25: 3410 | AK25: =AJ25/AH25 -> 0.077002981 | AM25: 44018 | AN25: 13612 | AO25: 13455 | AP25: =AO25/AM25 -> 0.30567041 | AR25: 148021 | AS25: 69751 | AT25: 69085 | AU25: =AT25/AR25 -> 0.46672432 | AV25: =AT25-AS25 -> -666 | AW25: 109992 | AX25: 6840 | AY25: 6970 | AZ25: =AY25/AW25 -> 0.063368245 | BB25: =AR25+AC25+X25+S25+N25+I25+D25+AM25+AH25+AW25 -> 534266 | BC25: =AS25+AD25+Y25+T25+O25+J25+E25+AN25+AI25+AX25 -> 108561 | BD25: =AT25+AE25+Z25+U25+P25+K25+F25+AO25+AJ25+AY25 -> 106923 | BE25: =BD25/BB25 -> 0.20013065
A26: 322632 | B26: BMW | C26: Siddharth | D26: 33417 | E26: 3094 | F26: 2486 | G26: =F26/D26 -> 0.074393273 | H26: =F26-E26 -> -608 | I26: 34830 | J26: 5754 | K26: 5059 | L26: =K26/I26 -> 0.14524835 | M26: =K26-J26 -> -695 | N26: 102671 | O26: 81655 | P26: 80193 | Q26: =P26/N26 -> 0.78106768 | R26: =P26-O26 -> -1462 | S26: 59050 | T26: 24289 | U26: 23488 | V26: =U26/S26 -> 0.39776461 | W26: =U26-T26 -> -801 | X26: 39584 | Y26: 4202 | Z26: 4049 | AA26: =Z26/X26 -> 0.1022888 | AB26: =Z26-Y26 -> -153 | AC26: 44469 | AD26: 6152 | AE26: 5400 | AF26: =AE26/AC26 -> 0.12143291 | AG26: =AE26-AD26 -> -752 | AH26: 23308 | AI26: 1440 | AJ26: 1437 | AK26: =AJ26/AH26 -> 0.061652651 | AM26: 77153 | AN26: 9974 | AO26: 6945 | AP26: =AO26/AM26 -> 0.090015942 | AR26: 70259 | AS26: 4847 | AT26: 4926 | AU26: =AT26/AR26 -> 0.070112014 | AV26: =AT26-AS26 -> 79 | AW26: 46427 | AX26: 3338 | AY26: 2644 | AZ26: =AY26/AW26 -> 0.05694962 | BB26: =AR26+AC26+X26+S26+N26+I26+D26+AM26+AH26+AW26 -> 531168 | BC26: =AS26+AD26+Y26+T26+O26+J26+E26+AN26+AI26+AX26 -> 144745 | BD26: =AT26+AE26+Z26+U26+P26+K26+F26+AO26+AJ26+AY26 -> 136627 | BE26: =BD26/BB26 -> 0.25721994
A27: 404904 | B27: JUST DO IT | C27: Siddharth | D27: 182 | E27: 17 | F27: 11 | G27: =F27/D27 -> 0.06043956 | H27: =F27-E27 -> -6 | I27: 209 | J27: 209 | K27: 205 | L27: =K27/I27 -> 0.98086124 | M27: =K27-J27 -> -4 | N27: 496 | O27: 144 | P27: 54 | Q27: =P27/N27 -> 0.10887097 | R27: =P27-O27 -> -90 | S27: 2022 | T27: 1168 | U27: 1240 | V27: =U27/S27 -> 0.6132542 | W27: =U27-T27 -> 72 | X27: 58 | Y27: 58 | Z27: 57 | AA27: =Z27/X27 -> 0.98275862 | AB27: =Z27-Y27 -> -1 | AC27: 12 | AD27: 12 | AE27: 6 | AF27: =AE27/AC27 -> 0.5 | AG27: =AE27-AD27 -> -6 | AH27: 35912 | AI27: 37 | AJ27: 30 | AK27: =AJ27/AH27 -> 0.00083537536 | AM27: 49368 | AN27: 183 | AO27: 118 | AP27: =AO27/AM27 -> 0.0023902123 | AR27: 9903 | AS27: 105 | AT27: 102 | AU27: =AT27/AR27 -> 0.010299909 | AV27: =AT27-AS27 -> -3 | AW27: 7288 | AX27: 0 | AZ27: =AY27/AW27 -> 0 | BB27: =AR27+AC27+X27+S27+N27+I27+D27+AM27+AH27+AW27 -> 105450 | BC27: =AS27+AD27+Y27+T27+O27+J27+E27+AN27+AI27+AX27 -> 1933 | BD27: =AT27+AE27+Z27+U27+P27+K27+F27+AO27+AJ27+AY27 -> 1823 | BE27: =BD27/BB27 -> 0.017287814
A28: 358973 | B28: AUDI | C28: Siddharth | D28: 44354 | E28: 3458 | F28: 2610 | G28: =F28/D28 -> 0.058844749 | H28: =F28-E28 -> -848 | I28: 35150 | J28: 4461 | K28: 3637 | L28: =K28/I28 -> 0.10347084 | M28: =K28-J28 -> -824 | N28: 119684 | O28: 92657 | P28: 91490 | Q28: =P28/N28 -> 0.76442966 | R28: =P28-O28 -> -1167 | S28: 55539 | T28: 20876 | U28: 20434 | V28: =U28/S28 -> 0.36792164 | W28: =U28-T28 -> -442 | X28: 60222 | Y28: 11540 | Z28: 9939 | AA28: =Z28/X28 -> 0.16503935 | AB28: =Z28-Y28 -> -1601 | AC28: 42743 | AD28: 4592 | AE28: 4276 | AF28: =AE28/AC28 -> 0.10003977 | AG28: =AE28-AD28 -> -316 | AH28: 46607 | AI28: 8298 | AJ28: 7571 | AK28: =AJ28/AH28 -> 0.16244341 | AM28: 65001 | AN28: 26046 | AO28: 25452 | AP28: =AO28/AM28 -> 0.39156321 | AR28: 41863 | AS28: 7073 | AT28: 6536 | AU28: =AT28/AR28 -> 0.15612832 | AV28: =AT28-AS28 -> -537 | AW28: 18163 | AX28: 1851 | AY28: 2034 | AZ28: =AY28/AW28 -> 0.11198591 | BB28: =AR28+AC28+X28+S28+N28+I28+D28+AM28+AH28+AW28 -> 529326 | BC28: =AS28+AD28+Y28+T28+O28+J28+E28+AN28+AI28+AX28 -> 180852 | BD28: =AT28+AE28+Z28+U28+P28+K28+F28+AO28+AJ28+AY28 -> 173979 | BE28: =BD28/BB28 -> 0.32868025
A29: 234394 | B29: NIKE | C29: Siddharth | D29: 699 | E29: 48 | F29: 41 | G29: =F29/D29 -> 0.058655222 | H29: =F29-E29 -> -7 | I29: 12178 | J29: 1038 | K29: 9 | L29: =K29/I29 -> 0.00073903761 | M29: =K29-J29 -> -1029 | N29: 2229 | O29: 512 | P29: 1522 | Q29: =P29/N29 -> 0.68281741 | R29: =P29-O29 -> 1010 | S29: 6478 | T29: 526 | U29: 523 | V29: =U29/S29 -> 0.080734795 | W29: =U29-T29 -> -3 | X29: 7087 | Y29: 1032 | Z29: 1019 | AA29: =Z29/X29 -> 0.14378439 | AB29: =Z29-Y29 -> -13 | AC29: 10322 | AD29: 2467 | AE29: 2326 | AF29: =AE29/AC29 -> 0.22534393 | AG29: =AE29-AD29 -> -141 | AH29: 81455 | AI29: 1287 | AJ29: 4647 | AK29: =AJ29/AH29 -> 0.057049905 | AM29: 72164 | AN29: 250 | AO29: 1030 | AP29: =AO29/AM29 -> 0.014273045 | AR29: 11011 | AS29: 541 | AT29: 540 | AU29: =AT29/AR29 -> 0.049041867 | AV29: =AT29-AS29 -> -1 | AW29: 6468 | AX29: 65 | AZ29: =AY29/AW29 -> 0 | BB29: =AR29+AC29+X29+S29+N29+I29+D29+AM29+AH29+AW29 -> 210091 | BC29: =AS29+AD29+Y29+T29+O29+J29+E29+AN29+AI29+AX29 -> 7766 | BD29: =AT29+AE29+Z29+U29+P29+K29+F29+AO29+AJ29+AY29 -> 11657 | BE29: =BD29/BB29 -> 0.05548548
A30: 359121 | B30: Canon | C30: Siddharth | D30: 5000 | E30: 417 | F30: 226 | G30: =F30/D30 -> 0.0452 | H30: =F30-E30 -> -191 | I30: 4944 | J30: 287 | K30: 274 | L30: =K30/I30 -> 0.055420712 | M30: =K30-J30 -> -13 | N30: 10003 | O30: 252 | P30: 246 | Q30: =P30/N30 -> 0.024592622 | R30: =P30-O30 -> -6 | S30: 2602 | T30: 0 | U30: 0 | V30: =U30/S30 -> 0 | W30: =U30-T30 -> 0 | X30: 3071 | Y30: 595 | Z30: 579 | AA30: =Z30/X30 -> 0.18853794 | AB30: =Z30-Y30 -> -16 | AC30: 1000 | AD30: 1 | AE30: 1 | AF30: =AE30/AC30 -> 0.001 | AG30: =AE30-AD30 -> 0 | AH30: 6888 | AI30: 198 | AJ30: 156 | AK30: =AJ30/AH30 -> 0.022648084 | AM30: 23783 | AN30: 813 | AO30: 332 | AP30: =AO30/AM30 -> 0.013959551 | AR30: 17594 | AS30: 134 | AT30: 84 | AU30: =AT30/AR30 -> 0.0047743549 | AV30: =AT30-AS30 -> -50 | AW30: 4167 | AX30: 273 | AY30: 169 | AZ30: =AY30/AW30 -> 0.040556755 | BB30: =AR30+AC30+X30+S30+N30+I30+D30+AM30+AH30+AW30 -> 79052 | BC30: =AS30+AD30+Y30+T30+O30+J30+E30+AN30+AI30+AX30 -> 2970 | BD30: =AT30+AE30+Z30+U30+P30+K30+F30+AO30+AJ30+AY30 -> 2067 | BE30: =BD30/BB30 -> 0.026147346
A31: 235110 | B31: Van Cleef & Arpels | C31: Siddharth | D31: 3036 | E31: 289 | F31: 126 | G31: =F31/D31 -> 0.041501976 | H31: =F31-E31 -> -163 | I31: 4175 | J31: 522 | K31: 266 | L31: =K31/I31 -> 0.063712575 | M31: =K31-J31 -> -256 | N31: 3309 | O31: 522 | P31: 196 | Q31: =P31/N31 -> 0.059232396 | R31: =P31-O31 -> -326 | S31: 7304 | T31: 891 | U31: 421 | V31: =U31/S31 -> 0.05763965 | W31: =U31-T31 -> -470 | X31: 5344 | Y31: 334 | Z31: 341 | AA31: =Z31/X31 -> 0.06380988 | AB31: =Z31-Y31 -> 7 | AC31: 5904 | AD31: 1350 | AE31: 1092 | AF31: =AE31/AC31 -> 0.18495935 | AG31: =AE31-AD31 -> -258 | AH31: 17075 | AI31: 778 | AJ31: 535 | AK31: =AJ31/AH31 -> 0.031332357 | AM31: 5238 | AN31: 1037 | AO31: 705 | AP31: =AO31/AM31 -> 0.13459336 | AR31: 11637 | AS31: 1804 | AT31: 650 | AU31: =AT31/AR31 -> 0.05585632 | AV31: =AT31-AS31 -> -1154 | AW31: 12750 | AX31: 2205 | AY31: 941 | AZ31: =AY31/AW31 -> 0.073803922 | BB31: =AR31+AC31+X31+S31+N31+I31+D31+AM31+AH31+AW31 -> 75772 | BC31: =AS31+AD31+Y31+T31+O31+J31+E31+AN31+AI31+AX31 -> 9732 | BD31: =AT31+AE31+Z31+U31+P31+K31+F31+AO31+AJ31+AY31 -> 5273 | BE31: =BD31/BB31 -> 0.06959035
A32: 5520961 | B32: VW | C32: Siddharth | D32: 34935 | E32: 1759 | F32: 1101 | G32: =F32/D32 -> 0.031515672 | H32: =F32-E32 -> -658 | I32: 20119 | J32: 371 | K32: 279 | L32: =K32/I32 -> 0.013867488 | M32: =K32-J32 -> -92 | N32: 8509 | O32: 376 | P32: 417 | Q32: =P32/N32 -> 0.049006934 | R32: =P32-O32 -> 41 | S32: 9964 | T32: 2172 | U32: 2059 | V32: =U32/S32 -> 0.20664392 | W32: =U32-T32 -> -113 | X32: 23740 | Y32: 868 | Z32: 851 | AA32: =Z32/X32 -> 0.035846672 | AB32: =Z32-Y32 -> -17 | AC32: 9932 | AD32: 1350 | AE32: 1206 | AF32: =AE32/AC32 -> 0.12142569 | AG32: =AE32-AD32 -> -144 | AH32: 18358 | AI32: 560 | AJ32: 746 | AK32: =AJ32/AH32 -> 0.040636235 | AM32: 17081 | AN32: 560 | AO32: 90 | AP32: =AO32/AM32 -> 0.0052690124 | AR32: 738 | AS32: 212 | AT32: 111 | AU32: =AT32/AR32 -> 0.1504065 | AV32: =AT32-AS32 -> -101 | AW32: 326 | AX32: 167 | AY32: 114 | AZ32: =AY32/AW32 -> 0.34969325 | BB32: =AR32+AC32+X32+S32+N32+I32+D32+AM32+AH32+AW32 -> 143702 | BC32: =AS32+AD32+Y32+T32+O32+J32+E32+AN32+AI32+AX32 -> 8395 | BD32: =AT32+AE32+Z32+U32+P32+K32+F32+AO32+AJ32+AY32 -> 6974 | BE32: =BD32/BB32 -> 0.048530988
A33: 407373 | B33: Office | C33: Siddharth | D33: 2484 | E33: 460 | F33: 77 | G33: =F33/D33 -> 0.03099839 | H33: =F33-E33 -> -383 | I33: 1313 | J33: 1313 | K33: 140 | L33: =K33/I33 -> 0.10662605 | M33: =K33-J33 -> -1173 | N33: 10575 | O33: 1536 | P33: 180 | Q33: =P33/N33 -> 0.017021277 | R33: =P33-O33 -> -1356 | S33: 10881 | T33: 1307 | U33: 75 | V33: =U33/S33 -> 0.0068927488 | W33: =U33-T33 -> -1232 | X33: 727 | Y33: 727 | Z33: 722 | AA33: =Z33/X33 -> 0.99312242 | AB33: =Z33-Y33 -> -5 | AC33: 47 | AD33: 46 | AE33: 47 | AF33: =AE33/AC33 -> 1 | AG33: =AE33-AD33 -> 1 | AH33: 1059 | AI33: 109 | AJ33: 64 | AK33: =AJ33/AH33 -> 0.060434372 | AM33: 4259 | AN33: 84 | AO33: 22 | AP33: =AO33/AM33 -> 0.0051655318 | AR33: 15319 | AS33: 536 | AT33: 306 | AU33: =AT33/AR33 -> 0.019975194 | AV33: =AT33-AS33 -> -230 | AW33: 16593 | AX33: 307 | AY33: 65 | AZ33: =AY33/AW33 -> 0.0039173145 | BB33: =AR33+AC33+X33+S33+N33+I33+D33+AM33+AH33+AW33 -> 63257 | BC33: =AS33+AD33+Y33+T33+O33+J33+E33+AN33+AI33+AX33 -> 6425 | BD33: =AT33+AE33+Z33+U33+P33+K33+F33+AO33+AJ33+AY33 -> 1698 | BE33: =BD33/BB33 -> 0.026842879
A34: 42439 | B34: MICROSOFT | C34: Siddharth | D34: 0 | E34: 0 | F34: 0 | G34: 0 | H34: =F34-E34 -> 0 | I34: 6 | J34: 6 | K34: 6 | L34: =K34/I34 -> 1 | M34: =K34-J34 -> 0 | N34: 7 | O34: 7 | P34: 7 | Q34: =P34/N34 -> 1 | R34: =P34-O34 -> 0 | S34: 1 | T34: 1 | U34: 2 | V34: =U34/S34 -> 2 | W34: =U34-T34 -> 1 | X34: 2 | Y34: 2 | Z34: 2 | AA34: =Z34/X34 -> 1 | AB34: =Z34-Y34 -> 0 | AF34: =AE34/AC34 -> #DIV/0! | AG34: =AE34-AD34 -> 0 | AH34: 15 | AI34: 4 | AK34: =AJ34/AH34 -> 0 | AP34: =AO34/AM34 -> #DIV/0! | AR34: 9427 | AS34: 6 | AT34: 3 | AU34: =AT34/AR34 -> 0.00031823486 | AV34: =AT34-AS34 -> -3 | AW34: 3143 | AX34: 37 | AY34: 1 | AZ34: =AY34/AW34 -> 0.00031816736 | BB34: =AR34+AC34+X34+S34+N34+I34+D34+AM34+AH34+AW34 -> 12601 | BC34: =AS34+AD34+Y34+T34+O34+J34+E34+AN34+AI34+AX34 -> 63 | BD34: =AT34+AE34+Z34+U34+P34+K34+F34+AO34+AJ34+AY34 -> 21 | BE34: =BD34/BB34 -> 0.0016665344
A35: 69913 | B35: AIR | C35: Siddharth | AH35: 94827 | AI35: 52301 | AJ35: 36106 | AK35: =AJ35/AH35 -> 0.38075654 | AM35: 172199 | AN35: 22301 | AO35: 17216 | AP35: =AO35/AM35 -> 0.099977352 | AR35: 27402 | AS35: 2896 | AT35: 3124 | AU35: =AT35/AR35 -> 0.11400628 | AW35: 18568 | AX35: 4246 | AY35: 4280 | AZ35: =AY35/AW35 -> 0.23050409 | BB35: =AR35+AC35+X35+S35+N35+I35+D35+AM35+AH35+AW35 -> 312996 | BC35: =AS35+AD35+Y35+T35+O35+J35+E35+AN35+AI35+AX35 -> 81744 | BD35: =AT35+AE35+Z35+U35+P35+K35+F35+AO35+AJ35+AY35 -> 60726 | BE35: =BD35/BB35 -> 0.19401526
A36: 553970 | B36: AIR FLIGHT | C36: Siddharth | AH36: 19269 | AI36: 12 | AJ36: 6 | AK36: =AJ36/AH36 -> 0.00031138097 | AM36: 9057 | AN36: 0 | AP36: =AO36/AM36 -> 0 | AR36: 7763 | AS36: 0 | AU36: =AT36/AR36 -> 0 | AW36: 4579 | AX36: 0 | AZ36: =AY36/AW36 -> 0 | BB36: =AR36+AC36+X36+S36+N36+I36+D36+AM36+AH36+AW36 -> 40668 | BC36: =AS36+AD36+Y36+T36+O36+J36+E36+AN36+AI36+AX36 -> 12 | BD36: =AT36+AE36+Z36+U36+P36+K36+F36+AO36+AJ36+AY36 -> 6 | BE36: =BD36/BB36 -> 0.00014753615
A37: 553949 | B37: AIR FORCE 1 | C37: Siddharth | AH37: 9904 | AI37: 120 | AJ37: 72 | AK37: =AJ37/AH37 -> 0.00726979 | AM37: 11863 | AN37: 52 | AO37: 206 | AP37: =AO37/AM37 -> 0.017364916 | AR37: 5003 | AS37: 0 | AU37: =AT37/AR37 -> 0 | AW37: 2877 | AX37: 0 | AZ37: =AY37/AW37 -> 0 | BB37: =AR37+AC37+X37+S37+N37+I37+D37+AM37+AH37+AW37 -> 29647 | BC37: =AS37+AD37+Y37+T37+O37+J37+E37+AN37+AI37+AX37 -> 172 | BD37: =AT37+AE37+Z37+U37+P37+K37+F37+AO37+AJ37+AY37 -> 278 | BE37: =BD37/BB37 -> 0.0093770027
A38: 553946 | B38: AIR FORCE I | C38: Siddharth | AH38: 21715 | AI38: 0 | AK38: =AJ38/AH38 -> 0 | AM38: 45163 | AN38: 0 | AP38: =AO38/AM38 -> 0 | AR38: 20 | AS38: 0 | AU38: =AT38/AR38 -> 0 | AW38: 5142 | AX38: 0 | AZ38: =AY38/AW38 -> 0 | BB38: =AR38+AC38+X38+S38+N38+I38+D38+AM38+AH38+AW38 -> 72040 | BC38: =AS38+AD38+Y38+T38+O38+J38+E38+AN38+AI38+AX38 -> 0 | BD38: =AT38+AE38+Z38+U38+P38+K38+F38+AO38+AJ38+AY38 -> 0 | BE38: =BD38/BB38 -> 0
A39: 553883 | B39: AIR MAX | C39: Siddharth | AH39: 37542 | AI39: 1476 | AJ39: 959 | AK39: =AJ39/AH39 -> 0.025544723 | AM39: 40249 | AN39: 406 | AO39: 149 | AP39: =AO39/AM39 -> 0.0037019553 | AR39: 20580 | AS39: 422 | AT39: 442 | AU39: =AT39/AR39 -> 0.021477162 | AW39: 21800 | AX39: 1836 | AY39: 2693 | AZ39: =AY39/AW39 -> 0.12353211 | BB39: =AR39+AC39+X39+S39+N39+I39+D39+AM39+AH39+AW39 -> 120171 | BC39: =AS39+AD39+Y39+T39+O39+J39+E39+AN39+AI39+AX39 -> 4140 | BD39: =AT39+AE39+Z39+U39+P39+K39+F39+AO39+AJ39+AY39 -> 4243 | BE39: =BD39/BB39 -> 0.035308019
A40: 98972 | B40: DUNK | C40: Siddharth | AH40: 52247 | AI40: 4945 | AJ40: 3766 | AK40: =AJ40/AH40 -> 0.072080694 | AM40: 75690 | AN40: 2145 | AO40: 384 | AP40: =AO40/AM40 -> 0.0050733254 | AR40: 608 | AS40: 0 | AU40: =AT40/AR40 -> 0 | AW40: 1527 | AX40: 0 | AZ40: =AY40/AW40 -> 0 | BB40: =AR40+AC40+X40+S40+N40+I40+D40+AM40+AH40+AW40 -> 130072 | BC40: =AS40+AD40+Y40+T40+O40+J40+E40+AN40+AI40+AX40 -> 7090 | BD40: =AT40+AE40+Z40+U40+P40+K40+F40+AO40+AJ40+AY40 -> 4150 | BE40: =BD40/BB40 -> 0.031905406
A41: 553886 | B41: MERCURIAL | C41: Siddharth | AH41: 10736 | AI41: 358 | AJ41: 478 | AK41: =AJ41/AH41 -> 0.0445231 | AM41: 41436 | AN41: 978 | AO41: 725 | AP41: =AO41/AM41 -> 0.017496863 | AR41: 40430 | AS41: 25230 | AT41: 22130 | AU41: =AT41/AR41 -> 0.54736582 | AW41: 31485 | AX41: 21687 | AY41: 23361 | AZ41: =AY41/AW41 -> 0.74197237 | BB41: =AR41+AC41+X41+S41+N41+I41+D41+AM41+AH41+AW41 -> 124087 | BC41: =AS41+AD41+Y41+T41+O41+J41+E41+AN41+AI41+AX41 -> 48253 | BD41: =AT41+AE41+Z41+U41+P41+K41+F41+AO41+AJ41+AY41 -> 46694 | BE41: =BD41/BB41 -> 0.3763005
A42: 553874 | B42: NIKE AIR | C42: Siddharth | AH42: 3198 | AI42: 6 | AJ42: 4 | AK42: =AJ42/AH42 -> 0.0012507817 | AM42: 11664 | AN42: 1 | AP42: =AO42/AM42 -> 0 | AR42: 5559 | AS42: 0 | AT42: 1 | AU42: =AT42/AR42 -> 0.00017988847 | AW42: 3455 | AX42: 0 | AZ42: =AY42/AW42 -> 0 | BB42: =AR42+AC42+X42+S42+N42+I42+D42+AM42+AH42+AW42 -> 23876 | BC42: =AS42+AD42+Y42+T42+O42+J42+E42+AN42+AI42+AX42 -> 7 | BD42: =AT42+AE42+Z42+U42+P42+K42+F42+AO42+AJ42+AY42 -> 5 | BE42: =BD42/BB42 -> 0.00020941531
A43: 553889 | B43: NIKE AIR VAPORMAX | C43: Siddharth | AH43: 21630 | AI43: 136 | AJ43: 94 | AK43: =AJ43/AH43 -> 0.004345816 | AM43: 46456 | AN43: 33 | AP43: =AO43/AM43 -> 0 | AR43: 3423 | AS43: 121 | AT43: 48 | AU43: =AT43/AR43 -> 0.014022787 | AW43: 2903 | AX43: 14 | AY43: 14 | AZ43: =AY43/AW43 -> 0.0048225973 | BB43: =AR43+AC43+X43+S43+N43+I43+D43+AM43+AH43+AW43 -> 74412 | BC43: =AS43+AD43+Y43+T43+O43+J43+E43+AN43+AI43+AX43 -> 304 | BD43: =AT43+AE43+Z43+U43+P43+K43+F43+AO43+AJ43+AY43 -> 156 | BE43: =BD43/BB43 -> 0.0020964361
A44: 1333843 | B44: Skims | C44: Siddharth | AK44: =AJ44/AH44 -> #DIV/0! | AP44: =AO44/AM44 -> #DIV/0! | AR44: 20875 | AS44: 20875 | AT44: 18657 | AU44: =AT44/AR44 -> 0.8937485 | AW44: 63382 | AX44: 63382 | AY44: 53563 | AZ44: =AY44/AW44 -> 0.8450822 | BB44: =AR44+AC44+X44+S44+N44+I44+D44+AM44+AH44+AW44 -> 84257 | BC44: =AS44+AD44+Y44+T44+O44+J44+E44+AN44+AI44+AX44 -> 84257 | BD44: =AT44+AE44+Z44+U44+P44+K44+F44+AO44+AJ44+AY44 -> 72220 | BE44: =BD44/BB44 -> 0.85713947
A45: 752852 | B45: MARTIN | C45: Purnima | D45: 19833 | E45: 17247 | F45: 19833 | G45: =F45/D45 -> 1 | H45: =F45-E45 -> 2586 | I45: 16777 | J45: 15865 | K45: 14937 | L45: =K45/I45 -> 0.89032604 | M45: =K45-J45 -> -928 | N45: 15163 | O45: 12470 | P45: 12324 | Q45: =P45/N45 -> 0.81276792 | R45: =P45-O45 -> -146 | S45: 20834 | T45: 13696 | U45: 11771 | V45: =U45/S45 -> 0.56498992 | W45: =U45-T45 -> -1925 | X45: 21899 | Y45: 17941 | Z45: 16093 | AA45: =Z45/X45 -> 0.73487374 | AB45: =Z45-Y45 -> -1848 | AC45: 83385 | AD45: 82391 | AE45: 86035 | AF45: =AE45/AC45 -> 1.0317803 | AG45: =AE45-AD45 -> 3644 | AH45: 10998 | AI45: 3666 | AJ45: 3384 | AK45: =AJ45/AH45 -> 0.30769231 | AM45: 10969 | AN45: 10969 | AO45: 9582 | AP45: =AO45/AM45 -> 0.87355274 | AR45: 21386 | AS45: 11298 | AT45: 7472 | AU45: =AT45/AR45 -> 0.34938745 | AV45: =AT45-AS45 -> -3826 | AW45: 11591 | AX45: 5007 | AY45: 4646 | AZ45: =AY45/AW45 -> 0.40082823 | BB45: =AR45+AC45+X45+S45+N45+I45+D45+AM45+AH45+AW45 -> 232835 | BC45: =AS45+AD45+Y45+T45+O45+J45+E45+AN45+AI45+AX45 -> 190550 | BD45: =AT45+AE45+Z45+U45+P45+K45+F45+AO45+AJ45+AY45 -> 186077 | BE45: =BD45/BB45 -> 0.79917968
A46: 237326 | B46: DR.MARTENS | C46: Purnima | D46: 23160 | E46: 16839 | F46: 15124 | G46: =F46/D46 -> 0.65302245 | H46: =F46-E46 -> -1715 | I46: 26347 | J46: 14045 | K46: 13951 | L46: =K46/I46 -> 0.52951 | M46: =K46-J46 -> -94 | N46: 15972 | O46: 1448 | P46: 1431 | Q46: =P46/N46 -> 0.08959429 | R46: =P46-O46 -> -17 | S46: 15946 | T46: 792 | U46: 560 | V46: =U46/S46 -> 0.035118525 | W46: =U46-T46 -> -232 | X46: 19864 | Y46: 4304 | Z46: 3766 | AA46: =Z46/X46 -> 0.18958921 | AB46: =Z46-Y46 -> -538 | AC46: 7012 | AD46: 960 | AE46: 398 | AF46: =AE46/AC46 -> 0.05675984 | AG46: =AE46-AD46 -> -562 | AH46: 17065 | AI46: 1861 | AJ46: 554 | AK46: =AJ46/AH46 -> 0.032464108 | AM46: 31794 | AN46: 2861 | AO46: 215 | AP46: =AO46/AM46 -> 0.0067622822 | AR46: 2009 | AS46: 22 | AT46: 4 | AU46: =AT46/AR46 -> 0.0019910403 | AV46: =AT46-AS46 -> -18 | AW46: 9875 | AX46: 1055 | AY46: 40 | AZ46: =AY46/AW46 -> 0.0040506329 | BB46: =AR46+AC46+X46+S46+N46+I46+D46+AM46+AH46+AW46 -> 169044 | BC46: =AS46+AD46+Y46+T46+O46+J46+E46+AN46+AI46+AX46 -> 44187 | BD46: =AT46+AE46+Z46+U46+P46+K46+F46+AO46+AJ46+AY46 -> 36043 | BE46: =BD46/BB46 -> 0.21321668
A47: 543860 | B47: CHANEL | C47: Purnima | D47: 11365 | E47: 3547 | F47: 4023 | G47: =F47/D47 -> 0.35398152 | H47: =F47-E47 -> 476 | I47: 5591 | J47: 535 | K47: 496 | L47: =K47/I47 -> 0.088714005 | M47: =K47-J47 -> -39 | N47: 5112 | O47: 727 | P47: 726 | Q47: =P47/N47 -> 0.14201878 | R47: =P47-O47 -> -1 | S47: 5062 | T47: 1012 | U47: 987 | V47: =U47/S47 -> 0.19498222 | W47: =U47-T47 -> -25 | X47: 6939 | Y47: 454 | Z47: 457 | AA47: =Z47/X47 -> 0.065859634 | AB47: =Z47-Y47 -> 3 | AC47: 12986 | AD47: 2098 | AE47: 2019 | AF47: =AE47/AC47 -> 0.15547513 | AG47: =AE47-AD47 -> -79 | AH47: 7426 | AI47: 98 | AJ47: 93 | AK47: =AJ47/AH47 -> 0.012523566 | AM47: 11447 | AN47: 224 | AO47: 93 | AP47: =AO47/AM47 -> 0.0081243994 | AR47: 65355 | AS47: 3824 | AT47: 2478 | AU47: =AT47/AR47 -> 0.037915997 | AV47: =AT47-AS47 -> -1346 | AW47: 41868 | AX47: 2627 | AY47: 1500 | AZ47: =AY47/AW47 -> 0.035826884 | BB47: =AR47+AC47+X47+S47+N47+I47+D47+AM47+AH47+AW47 -> 173151 | BC47: =AS47+AD47+Y47+T47+O47+J47+E47+AN47+AI47+AX47 -> 15146 | BD47: =AT47+AE47+Z47+U47+P47+K47+F47+AO47+AJ47+AY47 -> 12872 | BE47: =BD47/BB47 -> 0.074339738
...

Sheet Melo
A1: Brand ID | B1: Brand Name | C1: Manager | D1: Precision % | E1: Red Flags
A2: 326424 | B2: MagSafe | C2: Siddharth | D2: 0.4953575 | E2: 998
A3: 326425 | B3: Lightning | C3: Siddharth | D3: 0.31344226 | E3: 406
A4: 242269 | B4: Porsche | C4: Siddharth | D4: 0.029365997 | E4: 75
A5: 326696 | B5: MINI | C5: Siddharth | D5: 0.11161971 | E5: 0
A6: 373933 | B6: Sky | C6: NOI/Escalation | D6: 0.3258427
A7: 338729 | B7: KÄFER | C7: NOI/Escalation | D7: 0.18805283
A8: 586404 | B8: F-150 | C8: NOI/Escalation | D8: 0.066987952
A9: 110955 | B9: Apple | C9: Siddharth | D9: 0.22103749 | E9: 22149
A10: 213407 | B10: Chevrolet | C10: Siddharth | D10: 0.17851438 | E10: 3
A11: 553871 | B11: SWOOSH | C11: Siddharth | D11: 0.4379661 | E11: 360
A12: 338695 | B12: BULLI | C12: Siddharth | D12: 0.2802504 | E12: 57
A13: 326694 | B13: M | C13: Siddharth | D13: 0.45759643 | E13: 91
A14: 326429 | B14: Apple WATCH | C14: Siddharth | D14: 0.25080132 | E14: 5272
A15: 338748 | B15: VOLKSWAGEN | C15: Siddharth | D15: 0.028190722 | E15: 78
A16: 498419 | B16: JUMPMAN | C16: Siddharth | D16: 0.12139644 | E16: 36
A17: 239515 | B17: Mercedes-Benz | C17: Siddharth | D17: 0.44157187 | E17: 2
A18: 245805 | B18: AIR JORDAN | C18: Siddharth | D18: 0.11670625 | E18: 176
A19: 213405 | B19: Cadillac | C19: Siddharth | D19: 0.10249777 | E19: 1
A20: 382186 | B20: FORD | C20: Siddharth | D20: 0.080879076 | E20: 96
... A23: 220338 | B23: JEEP | C23: Siddharth | D23: 0.16364968 | E23: 69
A24: 364310 | B24: Skoda | C24: NOI/Escalation | D24: 0.1233193
A25: 422074 | B25: S LINE | C25: Siddharth | D25: 0.24423001 | E25: 0
A26: 553982 | B26: K I | C26: Siddharth | D26: 0.069218119 | E26: 0
A27: 338933 | B27: Xiaomi | C27: Siddharth | D27: 0.054237755 | E27: 85
A28: 327281 | B28: AirPods | C28: Siddharth | D28: 0.24730632 | E28: 1369
A29: 322632 | B29: BMW | C29: Siddharth | D29: 0.32684761 | E29: 655
A30: 404904 | B30: JUST DO IT | C30: Siddharth | D30: 0.13002639 | E30: 0
A31: 358973 | B31: AUDI | C31: Siddharth | D31: 0.34769181 | E31: 53
A32: 234394 | B32: NIKE | C32: Siddharth | D32: 0.11959043 | E32: 791
A33: 359121 | B33: Canon | C33: Siddharth | D33: 0.031890351 | E33: 377
A34: 235110 | B34: Van Cleef & Arpels | C34: Siddharth | D34: 0.07595372 | E34: 175
A35: 5520961 | B35: VW | C35: Siddharth | D35: 0.055810334 | E35: 0
A36: 407373 | B36: Office | C36: Siddharth | D36: 0.037415953 | E36: 0
... A62: 587965 | B62: Tiffany Blue | C62: Purnima | D62: 0.0023042085 | E62: 0
A63: 232415 | B63: ORAL-B | C63: NOI/Escalation | D63: 0.0029114312
A64: 195590 | B64: SONICARE | C64: Purnima | D64: 0.0068647372 | E64: 8
A65: 195649 | B65: AVENT | C65: NOI/Escalation | D65: 0.0034756703
A66: 333776 | B66: Hewlett Packard | C66: NOI/Escalation | D66: 0.020822313
A67: 471764 | B67: Dualshock (PS4) | C67: #N/A | D67: 0
...

Sheet Sids span
A1: Parent Brand | B1: Brand ID | C1: Brand Name | D1: Manager | E1: Precision % | F1: Red Flags | G1: suffle | H1: total brands | I1: 12 | J1: post 30th Nov Sids span
A2: APPLE | B2: 326424 | C2: MagSafe | D2: Siddharth | E2: 0.4953575 | F2: 998 | H2: High Priority | I2: 5
A3: APPLE | B3: 326433 | C3: iPhone | D3: Siddharth | E3: 0.34894437 | F3: 0 | H3: Medium Priority | I3: 3
A4: APPLE | B4: 326425 | C4: Lightning | D4: Siddharth | E4: 0.31344226 | F4: 406 | H4: Low Priority | I4: 4
A5: APPLE | B5: 326429 | C5: Apple WATCH | D5: Siddharth | E5: 0.25080132 | F5: 5272
A6: APPLE | B6: 327281 | C6: AirPods | D6: Siddharth | E6: 0.24730632 | F6: 1369
A7: APPLE | B7: 110955 | C7: Apple | D7: Siddharth | E7: 0.22103749 | F7: 22149
A8: AUDI | B8: 358973 | C8: AUDI | D8: Siddharth | E8: 0.34769181 | F8: 53
A9: AUDI | B9: 422074 | C9: S LINE | D9: Siddharth | E9: 0.24423001 | F9: 0
A10: BMW | B10: 326694 | C10: M | D10: Siddharth | E10: 0.45759643 | F10: 91
A11: BMW | B11: 322632 | C11: BMW | D11: Siddharth | E11: 0.32684761 | F11: 655
A12: BMW | B12: 326696 | C12: MINI | D12: Siddharth | E12: 0.11161971 | F12: 0
A13: Canon | B13: 359121 | C13: Canon | D13: Siddharth | E13: 0.031890351 | F13: 377 | G13: Ben
A14: DAIMLER AG | B14: 239515 | C14: Mercedes-Benz | D14: Siddharth | E14: 0.44157187 | F14: 2 | G14: Ben
A15: FIAT | B15: 220338 | C15: JEEP | D15: Siddharth | E15: 0.16364968 | F15: 69 | G15: Ben
A16: Ford | B16: 382186 | C16: FORD | D16: Siddharth | E16: 0.080879076 | F16: 96 | G16: Ben
A17: General Motors | B17: 213407 | C17: Chevrolet | D17: Siddharth | E17: 0.17851438 | F17: 3 | G17: Ben
A18: General Motors | B18: 213405 | C18: Cadillac | D18: Siddharth | E18: 0.10249777 | F18: 1 | G18: Ben
A19: MICROSOFT | B19: 407373 | C19: Office | D19: Siddharth | E19: 0.037415953 | F19: 0 | G19: Ben
A20: MICROSOFT | B20: 42439 | C20: MICROSOFT | D20: Siddharth | E20: 0.002117971 | F20: 230 | G20: Ben
A21: Nike | B21: 553871 | C21: SWOOSH | D21: Siddharth | E21: 0.4379661 | F21: 360
A22: Nike | B22: 553886 | C22: MERCURIAL | D22: Siddharth | E22: 0.24447255
A23: Nike | B23: 69913 | C23: AIR | D23: Siddharth | E23: 0.16048416
A24: Nike | B24: 404904 | C24: JUST DO IT | D24: Siddharth | E24: 0.13002639 | F24: 0
A25: Nike | B25: 498419 | C25: JUMPMAN | D25: Siddharth | E25: 0.12139644 | F25: 36
A26: Nike | B26: 234394 | C26: NIKE | D26: Siddharth | E26: 0.11959043 | F26: 791
A27: Nike | B27: 245805 | C27: AIR JORDAN | D27: Siddharth | E27: 0.11670625 | F27: 176
A28: Nike | B28: 553982 | C28: K I | D28: Siddharth | E28: 0.069218119 | F28: 0
A29: Nike | B29: 98972 | C29: DUNK | D29: Siddharth | E29: 0.03045648
A30: Nike | B30: 553883 | C30: AIR MAX | D30: Siddharth | E30: 0.017052921
A31: Nike | B31: 553949 | C31: AIR FORCE 1 | D31: Siddharth | E31: 0.0048601399
A32: Nike | B32: 553889 | C32: NIKE AIR VAPORMAX | D32: Siddharth | E32: 0.0016205421
A33: Nike | B33: 553874 | C33: NIKE AIR | D33: Siddharth | E33: 0.00019044717
A34: Nike | B34: 553970 | C34: AIR FLIGHT | D34: Siddharth | E34: 0.00010268522
A35: Nike | B35: 553946 | C35: AIR FORCE I | D35: Siddharth | E35: 0
A36: Porsche | B36: 242269 | C36: Porsche | D36: Siddharth | E36: 0.029365997 | F36: 75 | G36: Ben
A37: Richemont | B37: 235110 | C37: Van Cleef & Arpels | D37: Siddharth | E37: 0.07595372 | F37: 175 | G37: Ben
A38: Richemont | B38: 233930 | C38: CARTIER | D38: Siddharth | E38: 0.040092113 | F38: 65 | G38: Ben
A39: VOLKSWAGEN | B39: 338695 | C39: BULLI | D39: Siddharth | E39: 0.2802504 | F39: 57
A40: VOLKSWAGEN | B40: 5520961 | C40: VW | D40: Siddharth | E40: 0.055810334 | F40: 0
...

Sheet MoM Manager Wise
A1: Manager | B1: Jan'25 | E1: Feb'25 | H1: Mar'25 | K1: Apr'25 | N1: May'25 | Q1: Jun'25 | T1: Jul'25 | W1: Aug'25 | Z1: Sep'25 | AC1: Oct'25 | AF1: Overall
A2: Manager | B2: Total Audit Count | C2: Suppression Count | D2: Precision % | E2: Total Audit Count | F2: Suppression Count | G2: Precision % | H2: Total Audit Count | I2: Suppression Count | J2: Precision % | K2: Total Audit Count | L2: Suppression Count | M2: Precision % | N2: Total Audit Count | O2: Suppression Count | P2: Precision % | Q2: Total Audit Count | R2: Suppression Count | S2: Precision % | T2: Total Audit Count | U2: Suppression Count | V2: Precision % | W2: Total Audit Count | X2: Suppression Count | Y2: Precision % | Z2: Total Audit Count | AA2: Suppression Count | AB2: Precision % | AC2: Total Audit Count | AD2: Suppression Count | AE2: Precision % | AF2: Total Audit Count | AG2: Suppression Count | AH2: Precision %
A3: NOI/Escalation | B3: =SUM('MoM Brand Wise'!D92:D125) -> 110271 | C3: =SUM('MoM Brand Wise'!F92:F125) -> 13950 | D3: =C3/B3 -> 0.12650652 | E3: =SUM('MoM Brand Wise'!I92:I125) -> 100397 | F3: =SUM('MoM Brand Wise'!K92:K125) -> 18361 | G3: =F3/E3 -> 0.18288395 | H3: =SUM('MoM Brand Wise'!N92:N125) -> 102654 | I3: =SUM('MoM Brand Wise'!P92:P125) -> 27057 | J3: =I3/H3 -> 0.26357473 | K3: =SUM('MoM Brand Wise'!S92:S125) -> 113396 | L3: =SUM('MoM Brand Wise'!U92:U125) -> 27062 | M3: =L3/K3 -> 0.23865039 | N3: =SUM('MoM Brand Wise'!X92:X125) -> 71348 | O3: =SUM('MoM Brand Wise'!Z92:Z125) -> 35363 | P3: =O3/N3 -> 0.49564108 | Q3: =SUM('MoM Brand Wise'!AC92:AC125) -> 78196 | R3: =SUM('MoM Brand Wise'!AE92:AE125) -> 18251 | S3: =R3/Q3 -> 0.23340069 | T3: =SUM('MoM Brand Wise'!AH92:AH125) -> 110296 | U3: =SUM('MoM Brand Wise'!AJ92:AJ125) -> 32712 | V3: =U3/T3 -> 0.29658374 | W3: =SUM('MoM Brand Wise'!AM92:AM125) -> 128624 | X3: =SUM('MoM Brand Wise'!AO92:AO125) -> 10250 | Y3: =X3/W3 -> 0.079689638 | Z3: =SUM('MoM Brand Wise'!AR92:AR125) -> 106822 | AA3: =SUM('MoM Brand Wise'!AT92:AT125) -> 24947 | AB3: =AA3/Z3 -> 0.23353804 | AC3: =SUM('MoM Brand Wise'!AW92:AW125) -> 112642 | AD3: =SUM('MoM Brand Wise'!AY92:AY125) -> 37166 | AE3: =AD3/AC3 -> 0.32994798 | AF3: =AC3+Z3+T3+Q3+N3+K3+H3+E3+B3+W3 -> 1034646 | AG3: =AD3+AA3+U3+R3+O3+L3+I3+F3+C3+X3 -> 245119 | AH3: =AG3/AF3 -> 0.23691098
A4: Purnima | B4: =SUM('MoM Brand Wise'!D45:D91) -> 562205 | C4: =SUM('MoM Brand Wise'!F45:F91) -> 116999 | D4: =C4/B4 -> 0.20810736 | E4: =SUM('MoM Brand Wise'!I45:I91) -> 495256 | F4: =SUM('MoM Brand Wise'!K45:K91) -> 112892 | G4: =F4/E4 -> 0.22794676 | H4: =SUM('MoM Brand Wise'!N45:N91) -> 442944 | I4: =SUM('MoM Brand Wise'!P45:P91) -> 88344 | J4: =I4/H4 -> 0.19944733 | K4: =SUM('MoM Brand Wise'!S45:S91) -> 533469 | L4: =SUM('MoM Brand Wise'!U45:U91) -> 92535 | M4: =L4/K4 -> 0.173459 | N4: =SUM('MoM Brand Wise'!X45:X91) -> 474960 | O4: =SUM('MoM Brand Wise'!Z45:Z91) -> 122301 | P4: =O4/N4 -> 0.25749747 | Q4: =SUM('MoM Brand Wise'!AC45:AC91) -> 486092 | R4: =SUM('MoM Brand Wise'!AE45:AE91) -> 155743 | S4: =R4/Q4 -> 0.3203982 | T4: =SUM('MoM Brand Wise'!AH45:AH91) -> 407981 | U4: =SUM('MoM Brand Wise'!AJ45:AJ91) -> 42577 | V4: =U4/T4 -> 0.10436025 | W4: =SUM('MoM Brand Wise'!AM45:AM91) -> 922215 | X4: =SUM('MoM Brand Wise'!AO45:AO91) -> 62079 | Y4: =X4/W4 -> 0.067315105 | Z4: =SUM('MoM Brand Wise'!AR45:AR91) -> 1666659 | AA4: =SUM('MoM Brand Wise'!AT45:AT91) -> 108435 | AB4: =AA4/Z4 -> 0.065061299 | AC4: =SUM('MoM Brand Wise'!AW45:AW91) -> 1269718 | AD4: =SUM('MoM Brand Wise'!AY45:AY91) -> 128930 | AE4: =AD4/AC4 -> 0.10154223 | AF4: =AC4+Z4+T4+Q4+N4+K4+H4+E4+B4+W4 -> 7261499 | AG4: =AD4+AA4+U4+R4+O4+L4+I4+F4+C4+X4 -> 1030835 | AH4: =AG4/AF4 -> 0.14195898
A5: Siddharth | B5: =SUM('MoM Brand Wise'!D3:D44) -> 773310 | C5: =SUM('MoM Brand Wise'!F3:F44) -> 215823 | D5: =C5/B5 -> 0.27908989 | E5: =SUM('MoM Brand Wise'!I3:I44) -> 713628 | F5: =SUM('MoM Brand Wise'!K3:K44) -> 126655 | G5: =F5/E5 -> 0.17748042 | H5: =SUM('MoM Brand Wise'!N3:N44) -> 876043 | I5: =SUM('MoM Brand Wise'!P3:P44) -> 445320 | J5: =I5/H5 -> 0.50833121 | K5: =SUM('MoM Brand Wise'!S3:S44) -> 777659 | L5: =SUM('MoM Brand Wise'!U3:U44) -> 175815 | M5: =L5/K5 -> 0.22608238 | N5: =SUM('MoM Brand Wise'!X3:X44) -> 718917 | O5: =SUM('MoM Brand Wise'!Z3:Z44) -> 145168 | P5: =O5/N5 -> 0.20192595 | Q5: =SUM('MoM Brand Wise'!AC3:AC44) -> 607394 | R5: =SUM('MoM Brand Wise'!AE3:AE44) -> 116355 | S5: =R5/Q5 -> 0.19156429 | T5: =SUM('MoM Brand Wise'!AH3:AH44) -> 1301487 | U5: =SUM('MoM Brand Wise'!AJ3:AJ44) -> 244340 | V5: =U5/T5 -> 0.1877391 | W5: =SUM('MoM Brand Wise'!AM3:AM44) -> 2140868 | X5: =SUM('MoM Brand Wise'!AO3:AO44) -> 542467 | Y5: =X5/W5 -> 0.25338648 | Z5: =SUM('MoM Brand Wise'!AR3:AR44) -> 1398343 | AA5: =SUM('MoM Brand Wise'!AT3:AT44) -> 335580 | AB5: =AA5/Z5 -> 0.23998404 | AC5: =SUM('MoM Brand Wise'!AW3:AW44) -> 1169462 | AD5: =SUM('MoM Brand Wise'!AY3:AY44) -> 280906 | AE5: =AD5/AC5 -> 0.24020105 | AF5: =AC5+Z5+T5+Q5+N5+K5+H5+E5+B5+W5 -> 10477111 | AG5: =AD5+AA5+U5+R5+O5+L5+I5+F5+C5+X5 -> 2628429 | AH5: =AG5/AF5 -> 0.25087345
A6: Grand Total | B6: =SUM(B3:B5) -> 1445786 | C6: =SUM(C3:C5) -> 346772 | D6: =C6/B6 -> 0.23985016 | E6: =SUM(E3:E5) -> 1309281 | F6: =SUM(F3:F5) -> 257908 | G6: =F6/E6 -> 0.19698445 | H6: =SUM(H3:H5) -> 1421641 | I6: =SUM(I3:I5) -> 560721 | J6: =I6/H6 -> 0.39441814 | K6: =SUM(K3:K5) -> 1424524 | L6: =SUM(L3:L5) -> 295412 | M6: =L6/K6 -> 0.20737594 | N6: =SUM(N3:N5) -> 1265225 | O6: =SUM(O3:O5) -> 302832 | P6: =O6/N6 -> 0.23935031 | Q6: =SUM(Q3:Q5) -> 1171682 | R6: =SUM(R3:R5) -> 290349 | S6: =R6/Q6 -> 0.24780529 | T6: =SUM(T3:T5) -> 1819764 | U6: =SUM(U3:U5) -> 319629 | V6: =U6/T6 -> 0.17564311 | W6: =SUM(W3:W5) -> 3191707 | X6: =SUM(X3:X5) -> 614796 | Y6: =X6/W6 -> 0.19262294 | Z6: =SUM(Z3:Z5) -> 3171824 | AA6: =SUM(AA3:AA5) -> 468962 | AB6: =AA6/Z6 -> 0.14785247 | AC6: =SUM(AC3:AC5) -> 2551822 | AD6: =SUM(AD3:AD5) -> 447002 | AE6: =AD6/AC6 -> 0.17516974 | AF6: =SUM(AF3:AF5) -> 18773256 | AG6: =SUM(AG3:AG5) -> 3904383 | AH6: =AG6/AF6 -> 0.2079758

Sheet Melo Automated
A1: protected_brand_id | B1: protected_brand_name | C1: Jan | D1: Feb | E1: Mar | F1: Apr | G1: May | H1: Jun | I1: Jul | J1: Aug | K1: Sep | L1: Oct | M1: Nov | N1: Grand Total
A2: 198664 | B2: adidas | C2: 314517 | D2: 16712 | E2: 33603 | F2: 33006 | G2: 20704 | H2: 31354 | I2: 46830 | J2: 55137 | K2: 53942 | L2: 389946 | M2: 17122 | N2: 1012873
A3: 326433 | B3: iPhone | C3: 193238 | D3: 576800 | E3: 309961 | F3: 188209 | G3: 304080 | H3: 276681 | I3: 898126 | J3: 6358633 | K3: 1941009 | L3: 428058 | M3: 224562 | N3: 11699357
A4: 326424 | B4: MagSafe | C4: 108721 | D4: 27860 | E4: 88074 | F4: 85103 | G4: 102464 | H4: 51961 | I4: 133689 | J4: 59173 | K4: 308307 | L4: 92160 | M4: 64389 | N4: 1121901
A5: 110955 | B5: Apple | C5: 79313 | D5: 364431 | E5: 286821 | F5: 42014 | G5: 5338 | H5: 5185 | I5: 6100 | J5: 12032 | K5: 10363 | L5: 9892 | M5: 12589 | N5: 834078
A6: 239515 | B6: Mercedes Benz | C6: 34019 | D6: 25770 | E6: 45145 | F6: 43797 | G6: 20870 | H6: 85427 | I6: 37701 | J6: 47939 | K6: 41483 | L6: 40905 | M6: 32444 | N6: 455500
A7: 196635 | B7: The North face | C7: 31944 | D7: 12544 | E7: 7191 | F7: 7144 | G7: 1745 | H7: 2885 | I7: 4556 | J7: 3728 | K7: 4021 | L7: 62184 | M7: 5451 | N7: 143393
A8: 386197 | B8: Moncler | C8: 29508 | D8: 1008 | E8: 2703 | F8: 160 | G8: 105 | H8: 1024 | I8: 5385 | J8: 2458 | K8: 3268 | L8: 10035 | M8: 747 | N8: 56401
A9: 469031 | B9: Toyota | C9: 29094 | D9: 113136 | E9: 46943 | F9: 86998 | G9: 38220 | H9: 37001 | I9: 45828 | J9: 62362 | K9: 61192 | L9: 57466 | M9: 32463 | N9: 610703
A10: 322632 | B10: BMW | C10: 28315 | D10: 124551 | E10: 116482 | F10: 65950 | G10: 32442 | H10: 45258 | I10: 42485 | J10: 101265 | K10: 154025 | L10: 78034 | M10: 38644 | N10: 827451
A11: 213407 | B11: Chevrolet | C11: 25785 | D11: 22256 | E11: 68425 | F11: 49304 | G11: 84779 | H11: 21309 | I11: 29374 | J11: 45677 | K11: 42814 | L11: 43129 | M11: 29335 | N11: 462187
A12: 232762 | B12: Calvin Klein | C12: 19012 | D12: 7501 | E12: 10967 | F12: 12600 | G12: 4441 | H12: 5804 | I12: 7748 | J12: 4182 | K12: 2116 | L12: 4807 | M12: 1740 | N12: 80918
A13: 440088 | B13: NISSAN | C13: 13941 | D13: 47440 | E13: 16157 | F13: 33499 | G13: 15167 | H13: 15030 | I13: 30567 | J13: 33173 | K13: 32698 | L13: 21891 | M13: 23680 | N13: 283243
... A158: 195649 | B158: AVENT | C158: 78 | D158: 2909 | E158: 582 | F158: 266 | G158: 127 | H158: 98 | I158: 175 | J158: 176 | K158: 130 | L158: 236 | M158: 169 | N158: 4946
A159: 443390 | B159: 日産 | C159: 77 | D159: 328 | E159: 142 | F159: 124 | G159: 99 | H159: 45 | I159: 46 | J159: 443 | K159: 213 | L159: 11 | N159: 1528
A160: 338723 | B160: EOS | C160: 74 | D160: 71 | E160: 147 | F160: 112 | G160: 79 | H160: 86 | I160: 72 | J160: 83 | K160: 139 | L160: 85 | M160: 78 | N160: 1026
A161: 553954 | B161: FLYEASE | C161: 60 | D161: 4 | E161: 1 | F161: 7 | G161: 2 | H161: 3 | I161: 5 | J161: 8 | K161: 13 | L161: 34 | M161: 1 | N161: 138
A162: 413233 | B162: INVICTUS | C162: 59 | D162: 71 | E162: 196 | F162: 122 | G162: 214 | H162: 103 | I162: 173 | J162: 204 | K162: 262 | L162: 159 | M162: 127 | N162: 1690
A163: 338730 | B163: LAVIDA | C163: 59 | D163: 42 | E163: 87 | F163: 30 | G163: 17 | H163: 74 | I163: 44 | J163: 97 | K163: 31 | L163: 33 | M163: 25 | N163: 539
A164: 338683 | B164: PHAETON | C164: 54 | D164: 76 | E164: 71 | F164: 61 | G164: 33 | H164: 39 | I164: 20 | J164: 39 | K164: 57 | L164: 20 | M164: 31 | N164: 501
A165: 681443 | B165: LOEWE | C165: 51 | D165: 2911 | E165: 6415 | F165: 4887 | G165: 2541 | H165: 1972 | I165: 1135 | J165: 1093 | K165: 630 | L165: 1601 | M165: 1437 | N165: 24673
A166: 501960 | B166: Infiniti | C166: 51 | D166: 30 | E166: 84 | F166: 28 | G166: 35 | H166: 59 | I166: 55 | J166: 38 | K166: 203 | L166: 40 | M166: 58 | N166: 681
A167: 445325 | B167: RAM | C167: 49 | D167: 46 | E167: 23 | F167: 15 | G167: 409 | H167: 14 | I167: 4 | J167: 30 | K167: 113 | L167: 84 | M167: 42 | N167: 829
A168: 338739 | B168: Golf | C168: 46 | E168: 1 | F168: 4 | J168: 17 | K168: 1 | L168: 2 | N168: 71
A169: 508848 | B169: Rf | C169: 39 | D169: 39 | E169: 66 | F169: 189 | G169: 1302 | H169: 255 | I169: 1569 | J169: 72 | K169: 162 | L169: 736 | M169: 21 | N169: 4450
A170: 553900 | B170: ACG | C170: 39 | D170: 38 | E170: 84 | F170: 148 | G170: 27 | H170: 76 | I170: 519 | J170: 350 | K170: 614 | L170: 348 | M170: 12 | N170: 2255
A171: 360712 | B171: paco rabanne | C171: 39 | D171: 35 | E171: 123 | F171: 55 | G171: 29 | H171: 25 | I171: 46 | J171: 405 | K171: 780 | L171: 348 | M171: 54 | N171: 1939
A172: 487757 | B172: FENDI | C172: 38 | D172: 177 | E172: 340 | F172: 786 | G172: 252 | H172: 219 | I172: 291 | J172: 999 | K172: 2718 | L172: 1421 | M172: 5107 | N172: 12348
A173: 438481 | B173: LOUBOUTIN | C173: 33 | D173: 6 | E173: 29 | F173: 210 | G173: 2 | H173: 1 | J173: 1 | K173: 2 | L173: 3 | N173: 287
A174: 326700 | B174: BMW MOTORSPORT | C174: 32 | D174: 6 | E174: 14 | F174: 33 | G174: 13 | H174: 2 | I174: 95 | J174: 4729 | K174: 312 | L174: 127 | M174: 98 | N174: 5461
A175: 326712 | B175: B M W | C175: 30 | D175: 23 | E175: 22 | F175: 40 | G175: 70 | H175: 53 | I175: 11 | J175: 21 | K175: 34 | L175: 32 | M175: 2 | N175: 338
A176: 338744 | B176: Syncro | C176: 29 | D176: 32 | E176: 97 | F176: 282 | G176: 134 | H176: 38 | I176: 85 | J176: 105 | K176: 41 | L176: 50 | M176: 11 | N176: 904
A177: 338700 | B177: COCCINELLE | C177: 29 | D177: 16 | E177: 58 | F177: 69 | G177: 16 | H177: 41 | I177: 27 | J177: 47 | K177: 80 | L177: 63 | M177: 11 | N177: 457
A178: 1222406 | B178: F-350 | C178: 27 | D178: 34 | E178: 52 | F178: 55 | G178: 27 | H178: 37 | I178: 81 | J178: 146 | K178: 135 | L178: 48 | M178: 18 | N178: 660
A179: 338713 | B179: CADDY | C179: 27 | D179: 11 | E179: 27 | F179: 96 | G179: 27 | H179: 43 | I179: 47 | J179: 135 | K179: 68 | L179: 106 | M179: 45 | N179: 632
A180: 413238 | B180: 1 MILLION | C180: 25 | D180: 57 | E180: 57 | F180: 69 | G180: 50 | H180: 45 | I180: 102 | J180: 18 | K180: 22 | L180: 6 | M180: 15 | N180: 466
A181: 338726 | B181: TSI | C181: 23 | D181: 35 | E181: 64 | F181: 123 | G181: 277 | H181: 162 | I181: 69 | J181: 171 | K181: 125 | L181: 89 | M181: 309 | N181: 1447
A182: 407373 | B182: Office | C182: 23 | D182: 134 | E182: 202 | F182: 169 | G182: 105 | H182: 78 | I182: 40 | J182: 158 | K182: 83 | L182: 56 | M182: 76 | N182: 1124
A183: 404904 | B183: Just Do It | C183: 22 | D183: 25 | E183: 530 | F183: 368 | G183: 182 | H183: 37 | I183: 258 | J183: 247 | K183: 192 | L183: 144 | M183: 89 | N183: 2094
A184: 338703 | B184: R | C184: 21 | D184: 250 | E184: 339 | F184: 150 | G184: 30 | H184: 51 | I184: 33 | J184: 110 | K184: 44 | L184: 14 | M184: 14 | N184: 1056
...
